Workbook

Sheet Summary
B1: HSA INVESTMENT FINANCIAL PLAN
B2: Fidelity Aggressive Growth Strategy | Prepared for: Mildhail | May 2026
B3: ⚠ DISCLAIMER: This plan is educational only — not professional financial advice. A 15% annual return is an aspirational target, NOT a guarantee. All investments carry risk.
B5: CLIENT PROFILE
B6: Current Age | C6: 57 | E6: Target Retirement Age | F6: 62
B7: Years to Retirement | C7: 5 | E7: HSA Custodian | F7: Fidelity
B8: Current HSA Balance | C8: $3,200 | E8: Monthly Contribution | F8: $400 / month
B9: Annual Contribution | C9: $4,800 | E9: Catch-Up Eligible (Age 55+) | F9: Yes
B10: Other Retirement Savings | C10: Substantial (HSA is supplementary) | E10: Investment Style | F10: Aggressive Growth
B12: RECOMMENDED PORTFOLIO — AGGRESSIVE GROWTH ALLOCATION
B13: Ticker | C13: Fund Name | D13: Allocation | E13: Exp. Ratio | F13: Strategy Role | G13: Hist. 10yr Avg*
B14: FSELX | C14: Fidelity Select Semiconductors Portfolio | D14: 35% | E14: 0.68% | F14: High-Octane Growth Core | G14: ~28% / yr
B15: FTEC | C15: Fidelity MSCI Information Technology ETF | D15: 30% | E15: 0.08% | F15: Technology Growth Engine | G15: ~20% / yr
B16: FZROX | C16: Fidelity ZERO Total Market Index Fund | D16: 20% | E16: 0.00% | F16: Broad Market Foundation | G16: ~12% / yr
B17: FSSNX | C17: Fidelity Small Cap Index Fund | D17: 10% | E17: 0.025% | F17: Small-Cap Growth Premium | G17: ~11% / yr
B18: FZILX | C18: Fidelity ZERO International Index Fund | D18: 5% | E18: 0.00% | F18: International Diversifier | G18: ~7% / yr
B19: TOTAL / WEIGHTED AVG. EXP. RATIO | D19: 100% | E19: 0.27% | F19: * Historical averages only. Past performance ≠ future results. Source: Fidelity.com
B21: PROJECTED HSA VALUE AT RETIREMENT — AGE 62 (5 YEARS)
B22: Scenario | C22: Ann. Return | D22: Projected Balance | E22: Total Contributed | F22: Investment Gain | G22: Gain on Contrib.
B23: Bear Case | C23: 5% | D23: $31,302 | E23: $27,200 | F23: $4,102 | G23: 15.1%
B24: Base Case | C24: 10% | D24: $36,241 | E24: $27,200 | F24: $9,041 | G24: 33.2%
B25: ★ TARGET (15%) | C25: 15% | D25: $42,173 | E25: $27,200 | F25: $14,973 | G25: 55.0%
B26: Bull Case | C26: 20% | D26: $49,102 | E26: $27,200 | F26: $21,902 | G26: 80.5%
B28: KEY HSA RULES TO KNOW
B29: ✔ Triple Tax Advantage: Contributions pre-tax → Growth tax-free → Qualified withdrawals tax-free
B30: ✔ Qualified Medical Expense withdrawals are ALWAYS tax-free and penalty-free at any age
B31: ✔ Non-medical withdrawals before age 65: Taxed as ordinary income + 20% penalty
B32: ✔ Non-medical withdrawals at/after age 65: Taxed as ordinary income ONLY (like a traditional IRA)
B33: ✔ 2025 Contribution Limits: Self-only HDHP = $5,300 (incl. $1,000 catch-up) | Family = $9,550
B34: ✔ Your $4,800/year is within self-only limits — confirm your HDHP coverage type with Fidelity

Sheet Assumptions & Portfolio
B1: ASSUMPTIONS & PORTFOLIO INPUTS
B2: BLUE cells = hardcoded inputs you can change | BLACK cells = calculated formulas
B4: KEY INPUTS
B5: Input Description | C5: Value | D5: Notes
B6: Current HSA Balance ($) | C6: 3200 | D6: As of May 2026
B7: Monthly Contribution ($) | C7: 400 | D7: Consistent $400/mo assumed
B8: Annual Contribution ($) | C8: =C6*12 -> 38400 | D8: Auto-calc from monthly
B9: Current Age (years) | C9: 57
B10: Target Retirement Age (years) | C10: 62
B11: Years to Retirement | C11: =C9-C8 -> -38343 | D11: Auto-calc
B12: Bear Case Annual Return | C12: 0.05 | D12: Conservative / down-market
B13: Base Case Annual Return | C13: 0.1 | D13: Historical S&P 500 avg
B14: Target Annual Return | C14: 0.15 | D14: Aspirational — NOT guaranteed
B15: Bull Case Annual Return | C15: 0.2 | D15: Strong bull market scenario
B16: Bear Case Monthly Rate | C16: =C11/12 -> -3195.25 | D16: Auto-calc
B17: Base Case Monthly Rate | C17: =C12/12 -> 0.0041666667 | D17: Auto-calc
B18: Target Monthly Rate | C18: =C13/12 -> 0.0083333333 | D18: Auto-calc
B19: Bull Case Monthly Rate | C19: =C14/12 -> 0.0125 | D19: Auto-calc
B21: ℹ 2025 HSA Limits: Self-only HDHP = $4,300 base + $1,000 catch-up (55+) = $5,300 max | Family HDHP = $8,550 + $1,000 = $9,550 max | Your $4,800/yr is within self-only limits.
B23: PORTFOLIO ALLOCATION — DETAIL
B24: Ticker | C24: Allocation % | D24: Expense Ratio
B25: FSELX | C25: 0.35 | D25: 0.0068
B26: FTEC | C26: 0.3 | D26: 0.0008
B27: FZROX | C27: 0.2 | D27: 0
B28: FSSNX | C28: 0.1 | D28: 0.00025
B29: FZILX | C29: 0.05 | D29: 0
B30: TOTAL | C30: =SUM(C25:C29) -> 1 | D30: =SUMPRODUCT(C25:C29,D25:D29) -> 0.002645

Sheet 5-Year Projections
B1: 5-YEAR HSA GROWTH PROJECTIONS — FOUR SCENARIO ANALYSIS
B2: Monthly compounding | $400/month contributions | Start balance $3,200 | Rates linked from Assumptions sheet | Change inputs there to update all scenarios
B4: Year | C4: Age | D4: Bear Case (5% Ann.) | E4: Base Case (10% Ann.) | F4: ★ TARGET (15% Ann.) | G4: Bull Case (20% Ann.) | H4: Total Contributed
B5: 0 (Now) | C5: 57 | D5: 3200 | E5: 3200 | F5: 3200 | G5: 3200 | H5: 0
B6: 1 | C6: 58 | D6: =D5*(1+'Assumptions & Portfolio'!$C$16)^12+'Assumptions & Portfolio'!$C$7*((1+'Assumptions & Portfolio'!$C$16)^12-1)/'Assumptions & Portfolio'!$C$16 -> 3.6104375e+45 | E6: =E5*(1+'Assumptions & Portfolio'!$C$17)^12+'Assumptions & Portfolio'!$C$7*((1+'Assumptions & Portfolio'!$C$17)^12-1)/'Assumptions & Portfolio'!$C$17 -> 8275.2603 | F6: =F5*(1+'Assumptions & Portfolio'!$C$18)^12+'Assumptions & Portfolio'!$C$7*((1+'Assumptions & Portfolio'!$C$18)^12-1)/'Assumptions & Portfolio'!$C$18 -> 8561.3091 | G6: =G5*(1+'Assumptions & Portfolio'!$C$19)^12+'Assumptions & Portfolio'!$C$7*((1+'Assumptions & Portfolio'!$C$19)^12-1)/'Assumptions & Portfolio'!$C$19 -> 8858.559 | H6: ='Assumptions & Portfolio'!$C$6+1*12*'Assumptions & Portfolio'!$C$7 -> 8000
B7: 2 | C7: 59 | D7: =D6*(1+'Assumptions & Portfolio'!$C$16)^12+'Assumptions & Portfolio'!$C$7*((1+'Assumptions & Portfolio'!$C$16)^12-1)/'Assumptions & Portfolio'!$C$16 -> 4.0736778e+87 | E7: =E6*(1+'Assumptions & Portfolio'!$C$17)^12+'Assumptions & Portfolio'!$C$7*((1+'Assumptions & Portfolio'!$C$17)^12-1)/'Assumptions & Portfolio'!$C$17 -> 13610.18 | F7: =F6*(1+'Assumptions & Portfolio'!$C$18)^12+'Assumptions & Portfolio'!$C$7*((1+'Assumptions & Portfolio'!$C$18)^12-1)/'Assumptions & Portfolio'!$C$18 -> 14484.017 | G7: =G6*(1+'Assumptions & Portfolio'!$C$19)^12+'Assumptions & Portfolio'!$C$7*((1+'Assumptions & Portfolio'!$C$19)^12-1)/'Assumptions & Portfolio'!$C$19 -> 15426.757 | H7: ='Assumptions & Portfolio'!$C$6+2*12*'Assumptions & Portfolio'!$C$7 -> 12800
B8: 3 | C8: 60 | D8: =D7*(1+'Assumptions & Portfolio'!$C$16)^12+'Assumptions & Portfolio'!$C$7*((1+'Assumptions & Portfolio'!$C$16)^12-1)/'Assumptions & Portfolio'!$C$16 -> 4.5963545e+129 | E8: =E7*(1+'Assumptions & Portfolio'!$C$17)^12+'Assumptions & Portfolio'!$C$7*((1+'Assumptions & Portfolio'!$C$17)^12-1)/'Assumptions & Portfolio'!$C$17 -> 19218.045 | F8: =F7*(1+'Assumptions & Portfolio'!$C$18)^12+'Assumptions & Portfolio'!$C$7*((1+'Assumptions & Portfolio'!$C$18)^12-1)/'Assumptions & Portfolio'!$C$18 -> 21026.91 | G8: =G7*(1+'Assumptions & Portfolio'!$C$19)^12+'Assumptions & Portfolio'!$C$7*((1+'Assumptions & Portfolio'!$C$19)^12-1)/'Assumptions & Portfolio'!$C$19 -> 23050.822 | H8: ='Assumptions & Portfolio'!$C$6+3*12*'Assumptions & Portfolio'!$C$7 -> 17600
B9: 4 | C9: 61 | D9: =D8*(1+'Assumptions & Portfolio'!$C$16)^12+'Assumptions & Portfolio'!$C$7*((1+'Assumptions & Portfolio'!$C$16)^12-1)/'Assumptions & Portfolio'!$C$16 -> 5.1860936e+171 | E9: =E8*(1+'Assumptions & Portfolio'!$C$17)^12+'Assumptions & Portfolio'!$C$7*((1+'Assumptions & Portfolio'!$C$17)^12-1)/'Assumptions & Portfolio'!$C$17 -> 25112.819 | F9: =F8*(1+'Assumptions & Portfolio'!$C$18)^12+'Assumptions & Portfolio'!$C$7*((1+'Assumptions & Portfolio'!$C$18)^12-1)/'Assumptions & Portfolio'!$C$18 -> 28254.93 | G9: =G8*(1+'Assumptions & Portfolio'!$C$19)^12+'Assumptions & Portfolio'!$C$7*((1+'Assumptions & Portfolio'!$C$19)^12-1)/'Assumptions & Portfolio'!$C$19 -> 31900.491 | H9: ='Assumptions & Portfolio'!$C$6+4*12*'Assumptions & Portfolio'!$C$7 -> 22400
B10: 5 | C10: 62 | D10: =D9*(1+'Assumptions & Portfolio'!$C$16)^12+'Assumptions & Portfolio'!$C$7*((1+'Assumptions & Portfolio'!$C$16)^12-1)/'Assumptions & Portfolio'!$C$16 -> 5.8514998e+213 | E10: =E9*(1+'Assumptions & Portfolio'!$C$17)^12+'Assumptions & Portfolio'!$C$7*((1+'Assumptions & Portfolio'!$C$17)^12-1)/'Assumptions & Portfolio'!$C$17 -> 31309.181 | F10: =F9*(1+'Assumptions & Portfolio'!$C$18)^12+'Assumptions & Portfolio'!$C$7*((1+'Assumptions & Portfolio'!$C$18)^12-1)/'Assumptions & Portfolio'!$C$18 -> 36239.817 | G10: =G9*(1+'Assumptions & Portfolio'!$C$19)^12+'Assumptions & Portfolio'!$C$7*((1+'Assumptions & Portfolio'!$C$19)^12-1)/'Assumptions & Portfolio'!$C$19 -> 42172.783 | H10: ='Assumptions & Portfolio'!$C$6+5*12*'Assumptions & Portfolio'!$C$7 -> 27200
B12: Total Gain ($) | D12: =D10-H10 -> 5.8514998e+213 | E12: =E10-H10 -> 4109.1809 | F12: =F10-H10 -> 9039.8175 | G12: =G10-H10 -> 14972.783
B13: Return on Contrib. (%) | D13: =D12/H10 -> 2.1512867e+209 | E13: =E12/H10 -> 0.15107283 | F13: =F12/H10 -> 0.33234623 | G13: =G12/H10 -> 0.55046998
B15: ★ STRATEGY NOTE: With substantial other retirement savings, this HSA can sustain full market exposure. FSELX + FTEC historically drive the 15%+ target in bull cycles but expect higher short-term volatility. Do NOT panic-sell during corrections — the 5-year horizon is your shield.

Sheet Monthly Detail (15% Target)
B1: MONTHLY HSA GROWTH DETAIL — 15% TARGET SCENARIO (ASPIRATIONAL)
B2: Month-by-month tracking | Monthly rate 1.25% | $400/month contribution | Interest on beginning balance + contribution | Milestone years bolded
B4: Month | C4: Age | D4: Beg. Balance ($) | E4: Contribution ($) | F4: Interest Earned ($) | G4: End Balance ($) | H4: Cum. Contributed ($)
B5: 0 | C5: 57 | D5: 3200 | E5: 0 | F5: 0 | G5: 3200 | H5: 0
B6: 1 | D6: =G5 -> 3200 | E6: ='Assumptions & Portfolio'!$C$7 -> 400 | F6: =(D6+E6)*'Assumptions & Portfolio'!$C$18 -> 30 | G6: =D6+E6+F6 -> 3630 | H6: ='Assumptions & Portfolio'!$C$6+1*'Assumptions & Portfolio'!$C$7 -> 3600
B7: 2 | D7: =G6 -> 3630 | E7: ='Assumptions & Portfolio'!$C$7 -> 400 | F7: =(D7+E7)*'Assumptions & Portfolio'!$C$18 -> 33.583333 | G7: =D7+E7+F7 -> 4063.5833 | H7: ='Assumptions & Portfolio'!$C$6+2*'Assumptions & Portfolio'!$C$7 -> 4000
B8: 3 | D8: =G7 -> 4063.5833 | E8: ='Assumptions & Portfolio'!$C$7 -> 400 | F8: =(D8+E8)*'Assumptions & Portfolio'!$C$18 -> 37.196528 | G8: =D8+E8+F8 -> 4500.7799 | H8: ='Assumptions & Portfolio'!$C$6+3*'Assumptions & Portfolio'!$C$7 -> 4400
B9: 4 | D9: =G8 -> 4500.7799 | E9: ='Assumptions & Portfolio'!$C$7 -> 400 | F9: =(D9+E9)*'Assumptions & Portfolio'!$C$18 -> 40.839832 | G9: =D9+E9+F9 -> 4941.6197 | H9: ='Assumptions & Portfolio'!$C$6+4*'Assumptions & Portfolio'!$C$7 -> 4800
B10: 5 | D10: =G9 -> 4941.6197 | E10: ='Assumptions & Portfolio'!$C$7 -> 400 | F10: =(D10+E10)*'Assumptions & Portfolio'!$C$18 -> 44.513497 | G10: =D10+E10+F10 -> 5386.1332 | H10: ='Assumptions & Portfolio'!$C$6+5*'Assumptions & Portfolio'!$C$7 -> 5200
B11: 6 | D11: =G10 -> 5386.1332 | E11: ='Assumptions & Portfolio'!$C$7 -> 400 | F11: =(D11+E11)*'Assumptions & Portfolio'!$C$18 -> 48.217777 | G11: =D11+E11+F11 -> 5834.351 | H11: ='Assumptions & Portfolio'!$C$6+6*'Assumptions & Portfolio'!$C$7 -> 5600
B12: 7 | D12: =G11 -> 5834.351 | E12: ='Assumptions & Portfolio'!$C$7 -> 400 | F12: =(D12+E12)*'Assumptions & Portfolio'!$C$18 -> 51.952925 | G12: =D12+E12+F12 -> 6286.3039 | H12: ='Assumptions & Portfolio'!$C$6+7*'Assumptions & Portfolio'!$C$7 -> 6000
B13: 8 | D13: =G12 -> 6286.3039 | E13: ='Assumptions & Portfolio'!$C$7 -> 400 | F13: =(D13+E13)*'Assumptions & Portfolio'!$C$18 -> 55.719199 | G13: =D13+E13+F13 -> 6742.0231 | H13: ='Assumptions & Portfolio'!$C$6+8*'Assumptions & Portfolio'!$C$7 -> 6400
B14: 9 | D14: =G13 -> 6742.0231 | E14: ='Assumptions & Portfolio'!$C$7 -> 400 | F14: =(D14+E14)*'Assumptions & Portfolio'!$C$18 -> 59.516859 | G14: =D14+E14+F14 -> 7201.54 | H14: ='Assumptions & Portfolio'!$C$6+9*'Assumptions & Portfolio'!$C$7 -> 6800
B15: 10 | D15: =G14 -> 7201.54 | E15: ='Assumptions & Portfolio'!$C$7 -> 400 | F15: =(D15+E15)*'Assumptions & Portfolio'!$C$18 -> 63.346166 | G15: =D15+E15+F15 -> 7664.8861 | H15: ='Assumptions & Portfolio'!$C$6+10*'Assumptions & Portfolio'!$C$7 -> 7200
B16: 11 | D16: =G15 -> 7664.8861 | E16: ='Assumptions & Portfolio'!$C$7 -> 400 | F16: =(D16+E16)*'Assumptions & Portfolio'!$C$18 -> 67.207384 | G16: =D16+E16+F16 -> 8132.0935 | H16: ='Assumptions & Portfolio'!$C$6+11*'Assumptions & Portfolio'!$C$7 -> 7600
B17: 12 | C17: 58 | D17: =G16 -> 8132.0935 | E17: ='Assumptions & Portfolio'!$C$7 -> 400 | F17: =(D17+E17)*'Assumptions & Portfolio'!$C$18 -> 71.100779 | G17: =D17+E17+F17 -> 8603.1943 | H17: ='Assumptions & Portfolio'!$C$6+12*'Assumptions & Portfolio'!$C$7 -> 8000
B18: 13 | D18: =G17 -> 8603.1943 | E18: ='Assumptions & Portfolio'!$C$7 -> 400 | F18: =(D18+E18)*'Assumptions & Portfolio'!$C$18 -> 75.026619 | G18: =D18+E18+F18 -> 9078.2209 | H18: ='Assumptions & Portfolio'!$C$6+13*'Assumptions & Portfolio'!$C$7 -> 8400
B19: 14 | D19: =G18 -> 9078.2209 | E19: ='Assumptions & Portfolio'!$C$7 -> 400 | F19: =(D19+E19)*'Assumptions & Portfolio'!$C$18 -> 78.985174 | G19: =D19+E19+F19 -> 9557.2061 | H19: ='Assumptions & Portfolio'!$C$6+14*'Assumptions & Portfolio'!$C$7 -> 8800
B20: 15 | D20: =G19 -> 9557.2061 | E20: ='Assumptions & Portfolio'!$C$7 -> 400 | F20: =(D20+E20)*'Assumptions & Portfolio'!$C$18 -> 82.976717 | G20: =D20+E20+F20 -> 10040.183 | H20: ='Assumptions & Portfolio'!$C$6+15*'Assumptions & Portfolio'!$C$7 -> 9200
B21: 16 | D21: =G20 -> 10040.183 | E21: ='Assumptions & Portfolio'!$C$7 -> 400 | F21: =(D21+E21)*'Assumptions & Portfolio'!$C$18 -> 87.001523 | G21: =D21+E21+F21 -> 10527.184 | H21: ='Assumptions & Portfolio'!$C$6+16*'Assumptions & Portfolio'!$C$7 -> 9600
B22: 17 | D22: =G21 -> 10527.184 | E22: ='Assumptions & Portfolio'!$C$7 -> 400 | F22: =(D22+E22)*'Assumptions & Portfolio'!$C$18 -> 91.059869 | G22: =D22+E22+F22 -> 11018.244 | H22: ='Assumptions & Portfolio'!$C$6+17*'Assumptions & Portfolio'!$C$7 -> 10000
B23: 18 | D23: =G22 -> 11018.244 | E23: ='Assumptions & Portfolio'!$C$7 -> 400 | F23: =(D23+E23)*'Assumptions & Portfolio'!$C$18 -> 95.152035 | G23: =D23+E23+F23 -> 11513.396 | H23: ='Assumptions & Portfolio'!$C$6+18*'Assumptions & Portfolio'!$C$7 -> 10400
B24: 19 | D24: =G23 -> 11513.396 | E24: ='Assumptions & Portfolio'!$C$7 -> 400 | F24: =(D24+E24)*'Assumptions & Portfolio'!$C$18 -> 99.278302 | G24: =D24+E24+F24 -> 12012.675 | H24: ='Assumptions & Portfolio'!$C$6+19*'Assumptions & Portfolio'!$C$7 -> 10800
B25: 20 | D25: =G24 -> 12012.675 | E25: ='Assumptions & Portfolio'!$C$7 -> 400 | F25: =(D25+E25)*'Assumptions & Portfolio'!$C$18 -> 103.43895 | G25: =D25+E25+F25 -> 12516.113 | H25: ='Assumptions & Portfolio'!$C$6+20*'Assumptions & Portfolio'!$C$7 -> 11200
B26: 21 | D26: =G25 -> 12516.113 | E26: ='Assumptions & Portfolio'!$C$7 -> 400 | F26: =(D26+E26)*'Assumptions & Portfolio'!$C$18 -> 107.63428 | G26: =D26+E26+F26 -> 13023.748 | H26: ='Assumptions & Portfolio'!$C$6+21*'Assumptions & Portfolio'!$C$7 -> 11600
B27: 22 | D27: =G26 -> 13023.748 | E27: ='Assumptions & Portfolio'!$C$7 -> 400 | F27: =(D27+E27)*'Assumptions & Portfolio'!$C$18 -> 111.86456 | G27: =D27+E27+F27 -> 13535.612 | H27: ='Assumptions & Portfolio'!$C$6+22*'Assumptions & Portfolio'!$C$7 -> 12000
B28: 23 | D28: =G27 -> 13535.612 | E28: ='Assumptions & Portfolio'!$C$7 -> 400 | F28: =(D28+E28)*'Assumptions & Portfolio'!$C$18 -> 116.1301 | G28: =D28+E28+F28 -> 14051.742 | H28: ='Assumptions & Portfolio'!$C$6+23*'Assumptions & Portfolio'!$C$7 -> 12400
B29: 24 | C29: 59 | D29: =G28 -> 14051.742 | E29: ='Assumptions & Portfolio'!$C$7 -> 400 | F29: =(D29+E29)*'Assumptions & Portfolio'!$C$18 -> 120.43119 | G29: =D29+E29+F29 -> 14572.174 | H29: ='Assumptions & Portfolio'!$C$6+24*'Assumptions & Portfolio'!$C$7 -> 12800
B30: 25 | D30: =G29 -> 14572.174 | E30: ='Assumptions & Portfolio'!$C$7 -> 400 | F30: =(D30+E30)*'Assumptions & Portfolio'!$C$18 -> 124.76811 | G30: =D30+E30+F30 -> 15096.942 | H30: ='Assumptions & Portfolio'!$C$6+25*'Assumptions & Portfolio'!$C$7 -> 13200
B31: 26 | D31: =G30 -> 15096.942 | E31: ='Assumptions & Portfolio'!$C$7 -> 400 | F31: =(D31+E31)*'Assumptions & Portfolio'!$C$18 -> 129.14118 | G31: =D31+E31+F31 -> 15626.083 | H31: ='Assumptions & Portfolio'!$C$6+26*'Assumptions & Portfolio'!$C$7 -> 13600
B32: 27 | D32: =G31 -> 15626.083 | E32: ='Assumptions & Portfolio'!$C$7 -> 400 | F32: =(D32+E32)*'Assumptions & Portfolio'!$C$18 -> 133.55069 | G32: =D32+E32+F32 -> 16159.634 | H32: ='Assumptions & Portfolio'!$C$6+27*'Assumptions & Portfolio'!$C$7 -> 14000
B33: 28 | D33: =G32 -> 16159.634 | E33: ='Assumptions & Portfolio'!$C$7 -> 400 | F33: =(D33+E33)*'Assumptions & Portfolio'!$C$18 -> 137.99695 | G33: =D33+E33+F33 -> 16697.631 | H33: ='Assumptions & Portfolio'!$C$6+28*'Assumptions & Portfolio'!$C$7 -> 14400
B34: 29 | D34: =G33 -> 16697.631 | E34: ='Assumptions & Portfolio'!$C$7 -> 400 | F34: =(D34+E34)*'Assumptions & Portfolio'!$C$18 -> 142.48025 | G34: =D34+E34+F34 -> 17240.111 | H34: ='Assumptions & Portfolio'!$C$6+29*'Assumptions & Portfolio'!$C$7 -> 14800
B35: 30 | D35: =G34 -> 17240.111 | E35: ='Assumptions & Portfolio'!$C$7 -> 400 | F35: =(D35+E35)*'Assumptions & Portfolio'!$C$18 -> 147.00092 | G35: =D35+E35+F35 -> 17787.112 | H35: ='Assumptions & Portfolio'!$C$6+30*'Assumptions & Portfolio'!$C$7 -> 15200
B36: 31 | D36: =G35 -> 17787.112 | E36: ='Assumptions & Portfolio'!$C$7 -> 400 | F36: =(D36+E36)*'Assumptions & Portfolio'!$C$18 -> 151.55926 | G36: =D36+E36+F36 -> 18338.671 | H36: ='Assumptions & Portfolio'!$C$6+31*'Assumptions & Portfolio'!$C$7 -> 15600
B37: 32 | D37: =G36 -> 18338.671 | E37: ='Assumptions & Portfolio'!$C$7 -> 400 | F37: =(D37+E37)*'Assumptions & Portfolio'!$C$18 -> 156.15559 | G37: =D37+E37+F37 -> 18894.827 | H37: ='Assumptions & Portfolio'!$C$6+32*'Assumptions & Portfolio'!$C$7 -> 16000
B38: 33 | D38: =G37 -> 18894.827 | E38: ='Assumptions & Portfolio'!$C$7 -> 400 | F38: =(D38+E38)*'Assumptions & Portfolio'!$C$18 -> 160.79022 | G38: =D38+E38+F38 -> 19455.617 | H38: ='Assumptions & Portfolio'!$C$6+33*'Assumptions & Portfolio'!$C$7 -> 16400
B39: 34 | D39: =G38 -> 19455.617 | E39: ='Assumptions & Portfolio'!$C$7 -> 400 | F39: =(D39+E39)*'Assumptions & Portfolio'!$C$18 -> 165.46347 | G39: =D39+E39+F39 -> 20021.08 | H39: ='Assumptions & Portfolio'!$C$6+34*'Assumptions & Portfolio'!$C$7 -> 16800
B40: 35 | D40: =G39 -> 20021.08 | E40: ='Assumptions & Portfolio'!$C$7 -> 400 | F40: =(D40+E40)*'Assumptions & Portfolio'!$C$18 -> 170.17567 | G40: =D40+E40+F40 -> 20591.256 | H40: ='Assumptions & Portfolio'!$C$6+35*'Assumptions & Portfolio'!$C$7 -> 17200
B41: 36 | C41: 60 | D41: =G40 -> 20591.256 | E41: ='Assumptions & Portfolio'!$C$7 -> 400 | F41: =(D41+E41)*'Assumptions & Portfolio'!$C$18 -> 174.92713 | G41: =D41+E41+F41 -> 21166.183 | H41: ='Assumptions & Portfolio'!$C$6+36*'Assumptions & Portfolio'!$C$7 -> 17600
...

Sheet Fund Research Notes
B1: FUND RESEARCH NOTES & INVESTMENT RATIONALE
B2: ⚠ Past performance is NOT indicative of future results. All figures are approximate historical averages. Verify at Fidelity.com before investing.
B4: Ticker | C4: Fund Description | D4: Exp. Ratio | E4: Target Alloc. | F4: Investment Thesis | G4: Key Risks
B5: FSELX | C5: Fidelity Select Semiconductors Portfolio Actively managed. Focuses on semiconductor manufacturers, designers & equipment makers. Top holdings include NVIDIA, TSMC, ASML, Broadcom, Applied Materials. | D5: 0.68% | E5: 35% | F5: Semiconductors are the fundamental input for AI, EVs, data centers, 5G, and robotics. This is where technological leverage is greatest. FSELX has been one of Fidelity's top performers over 10+ years. High ER is justified by active management in a complex sector. | G5: Extreme cyclicality — semiconductor stocks can fall 40-50% in downturns. Single-sector concentration. Active management risk. Highest ER in portfolio.
B6: FTEC | C6: Fidelity MSCI Information Technology ETF Passive ETF tracking the MSCI USA IMI IT Index. Broad tech exposure: Apple, Microsoft, NVIDIA, Salesforce, etc. Near-zero cost. | D6: 0.08% | E6: 30% | F6: Provides diversified tech-sector exposure at minimal cost. Complements FSELX by capturing software, IT services, and hardware alongside semiconductors. Lower volatility than FSELX while still capturing major tech growth trends. | G6: Technology-sector concentration. High P/E valuations sensitive to rising interest rates. Overlaps somewhat with FSELX in semiconductor names.
B7: FZROX | C7: Fidelity ZERO Total Market Index Fund Zero-expense-ratio index fund tracking the Fidelity U.S. Total Investable Market Index. ~2,700 U.S. companies across all market caps. | D7: 0.00% | E7: 20% | F7: Portfolio stabilizer with literally zero cost. Ensures participation in broad U.S. market growth including sectors that may outperform tech in a given cycle. Acts as the diversified anchor to offset sector concentration risk. | G7: Will underperform in strong tech bull markets. Provides market-rate return only. No unique alpha over a low-cost index.
B8: FSSNX | C8: Fidelity Small Cap Index Fund Tracks the Russell 2000 Index of small-cap U.S. equities. Broadly diversified across ~2,000 smaller companies. | D8: 0.025% | E8: 10% | F8: Captures the documented 'small-cap premium' — small companies have historically outperformed large caps over long periods. Adds return potential and diversification outside mega-cap tech names that dominate other holdings. | G8: Higher volatility than large-cap funds. Small caps often fall harder in recessions and take longer to recover. Less liquidity.
B9: FZILX | C9: Fidelity ZERO International Index Fund Zero-expense-ratio fund tracking the Fidelity Global ex U.S. Index. Covers developed and emerging markets outside the United States. | D9: 0.00% | E9: 5% | F9: Currency diversification and international exposure at zero cost. Hedge against U.S.-specific economic or political risk. Small 5% allocation keeps the portfolio U.S.-growth-focused while adding a global buffer. | G9: Currency risk, geopolitical risk, withholding taxes on dividends. International equities have underperformed U.S. equities over the past decade.
B11: REBALANCING STRATEGY: Review and rebalance annually. If any single fund drifts >5% from target, redirect new contributions (not redemptions) to underweight funds to avoid taxable events. Reassess allocation at age 60 and shift 10-15% to FXNAX (bond index) for capital preservation.

Sheet Current Holdings Analysis
B1: CURRENT HOLDINGS ANALYSIS — PORTFOLIO SNAPSHOT (MAY 2026)
B2: ⚠ For educational purposes only — not professional financial advice. This analysis assumes the portfolio shown is separate from or overlapping with the HSA.
B4: CURRENT HOLDINGS BREAKDOWN
B5: Holding | C5: Shares / Qty | D5: Current Value | E5: Allocation % | F5: Type / Status | G5: Assessment
B6: NFLX 106 Call Jun 18 2026 | C6: 1 contract | D6: 27 | E6: 0.0074740691 | F6: Short-Term Options ⚠ EXPIRES ~6 WEEKS | G6: CRITICAL: Cannot hold to age 62. Expires Jun 18, 2026. Down 10% today. Needs an exit decision now — let expire or close & redeploy.
B7: FNARX Fidelity Advisor New Insights | C7: 19.075 shares | D7: 1236.63 | E7: 0.34232067 | F7: Actively Managed Growth Mutual Fund | G7: Growth-oriented but likely carries higher expense ratio than index alternatives. Review ER. Could be consolidated into FSELX or FTEC for lower cost & higher growth.
B8: FNILX Fidelity ZERO Large Cap Index | C8: 47.601 shares | D8: 1255.23 | E8: 0.34746947 | F8: Passive Index Fund ✔ 0% Expense Ratio | G8: STRONGEST position in portfolio. Zero cost, broad large-cap exposure. Aligns with recommended strategy. HOLD and consider increasing allocation.
B9: ONDS Ondas Holdings Inc. | C9: 55 shares | D9: 498.3 | E9: 0.1379381 | F9: Individual Small-Cap Stock ⚠ HIGHLY SPECULATIVE | G9: Micro-cap individual stock with binary risk profile. Not suitable as a core retirement holding. Could go to zero or multiply — inappropriate concentration risk.
B10: QPISQ Cash / Money Market | C10: 595.33 shares | D10: 595.33 | E10: 0.16479769 | F10: Cash / Money Market ⚠ RETURN DRAG | G10: At ~3-4% money market rates, this 16.5% allocation significantly drags portfolio returns. Idle capital that should be deployed into growth funds.
B11: TOTAL PORTFOLIO VALUE | D11: 3612.49 | E11: 1 | F11: Note: NFLX Call value ($27) is the contract premium, not 100× notional.
B13: PORTFOLIO WEAKNESSES VS. AGGRESSIVE GROWTH TARGET
B14: ❶ Expiring Option | C14: NFLX 106 Call expires June 18, 2026 — within 6 weeks. The concept of 'holding to age 62' does not apply. Needs a decision now.
B15: ❷ Cash Drag (16.5%) | C15: QPISQ earns ~3-4% while your growth target is 15%. $595 sitting idle costs you roughly $660+ in foregone growth over 5 years.
B16: ❸ Single-Stock Risk (13.8%) | C16: ONDS is a speculative micro-cap. Individual stocks can go to zero. Concentration in a single name contradicts sound retirement planning.
B17: ❹ No Semiconductor Exposure | C17: The highest-return Fidelity fund (FSELX, ~28% historical 10yr avg) is absent. This is the primary driver of the 15% target in our recommended strategy.
B18: ❺ Missing FSELX, FTEC, FSSNX, FZILX | C18: Only FNILX aligns with the recommended aggressive portfolio. 70%+ of the portfolio is misaligned with the growth strategy we built.

Sheet Portfolio Comparison (5yr)
B1: 5-YEAR PROJECTION — CURRENT HOLDINGS vs. RECOMMENDED STRATEGY
B2: Current portfolio: ~$3,612 starting value, NO additional contributions assumed | Recommended strategy: $3,612 starting value + $400/month contributions | All returns are projections, not guarantees.
D4: CURRENT PORTFOLIO (No New Contributions) | G4: RECOMMENDED STRATEGY ($400/mo Contributions) | J4: ADVANTAGE (Recommended vs. Current)
B5: Year | C5: Age | D5: Blended 8% Return Est. | E5: If FNILX Only (10% Return) | G5: Target (15%) W/ Contributions | H5: Base (10%) W/ Contributions | J5: Extra Value @ 15% Target
B6: 0 (Now) | C6: 57 | D6: 3612.49 | E6: 3612.49 | G6: 3612.49 | H6: 3612.49 | J6: —
B7: 1 | C7: 58 | D7: 3901.4892 | E7: 3973.739 | G7: 9337.3587 | H7: 9016.9921 | J7: 5435.8695
B8: 2 | C8: 59 | D8: 4213.6083 | E8: 4371.1129 | G8: 15982.526 | H8: 14987.416 | J8: 11768.917
B9: 3 | C9: 60 | D9: 4550.697 | E9: 4808.2242 | G9: 23695.934 | H9: 21583.022 | J9: 19145.237
B10: 4 | C10: 61 | D10: 4914.7528 | E10: 5289.0466 | G10: 32649.307 | H10: 28869.274 | J10: 27734.554
B11: 5 | C11: 62 | D11: 5307.933 | E11: 5817.9513 | G11: 43041.975 | H11: 36918.491 | J11: 37734.042
B13: AT AGE 62 (Year 5): | D13: 5307.933 | E13: 5817.9513 | G13: 43041.975 | H13: 36918.491 | J13: 37734.042
B14: Gain vs. Start: | D14: 1695.443 | E14: 2205.4613 | G14: 39429.485 | H14: 33306.001 | J14: 37734.042
B16: ★ BOTTOM LINE: Holding the current portfolio as-is (blended ~8% return, no new contributions) projects to ~$5,308 at age 62 — a gain of ~$1,695 on your starting $3,612. Transitioning to the recommended aggressive strategy AND adding $400/month projects to ~$43,042 — a difference of ~$37,734 in your favor. The gap is driven by two factors: (1) the $400/month contributions compounding at 15% vs. no contributions, and (2) the recommended portfolio's higher-growth fund mix (FSELX/FTEC) vs. a blend with cash drag and a speculative individual stock. The NFLX call option also needs an exit plan within the next 6 weeks.
B18: INDIVIDUAL HOLDING PROJECTIONS — CURRENT PORTFOLIO (HOLD SCENARIO, NO NEW CONTRIBUTIONS)
B19: Holding | C19: Current Value | D19: Assumed Rate | E19: Yr 1 | F19: Yr 2 | G19: Yr 3 | H19: Yr 4 | I19: Yr 5 (Age 62) | J19: Assessment
B20: NFLX 106 Call Jun 18 2026 | C20: 27 | D20: 0 | E20: — | F20: — | G20: — | H20: — | I20: — | J20: EXPIRES JUN 2026 — Cannot project. Assume $0 by Yr 1.
B21: FNARX Fidelity Advisor Growth | C21: 1236.63 | D21: 0.08 | E21: 1335.5604 | F21: 1442.4052 | G21: 1557.7977 | H21: 1682.4215 | I21: 1817.0152 | J21: 8% assumed (growth fund, higher ER than index). Consider switching to FSELX.
B22: FNILX Fidelity ZERO Large Cap | C22: 1255.23 | D22: 0.1 | E22: 1380.753 | F22: 1518.8283 | G22: 1670.7111 | H22: 1837.7822 | I22: 2021.5605 | J22: 10% assumed (historical S&P 500 avg). KEEP — aligns with strategy.
B23: ONDS Ondas Holdings (speculative) | C23: 498.3 | D23: 0 | E23: 498.3 | F23: 498.3 | G23: 498.3 | H23: 498.3 | I23: 498.3 | J23: 0% assumed (conservative — speculative micro-cap could go to $0 or 5x). HIGH RISK.
B24: QPISQ Cash / Money Market | C24: 595.33 | D24: 0.04 | E24: 619.1432 | F24: 643.90893 | G24: 669.66529 | H24: 696.4519 | I24: 724.30997 | J24: 4% assumed (money market rate). REDEPLOY into growth funds.
B25: TOTAL (Hold Scenario, No Contributions) | E25: 3833.7566 | F25: 4103.4425 | G25: 4396.4741 | H25: 4714.9556 | I25: 5061.1856 | J25: At age 62: ~$5,061 (vs. Recommended $43,042)
